2019-11-15 12:07:47,165 INFO: Microblog Startup... [in /home/harshalgangurde/Workspace/Flask/microblog/app/__init__.py:29]
2019-11-15 12:08:50,821 INFO: Microblog Startup... [in /home/harshalgangurde/Workspace/Flask/microblog/app/__init__.py:29]
2019-11-15 12:09:10,578 ERROR: Exception on /edit-profile [POST] [in /usr/local/lib/python3.7/dist-packages/flask/app.py:1891]
Traceback (most recent call last):
  File "/usr/local/lib/python3.7/dist-packages/sqlalchemy/engine/base.py", line 1246, in _execute_context
    cursor, statement, parameters, context
  File "/usr/local/lib/python3.7/dist-packages/sqlalchemy/engine/default.py", line 581, in do_execute
    cursor.execute(statement, parameters)
sqlite3.IntegrityError: UNIQUE constraint failed: user.username

The above exception was the direct cause of the following exception:

Traceback (most recent call last):
  File "/usr/local/lib/python3.7/dist-packages/flask/app.py", line 2446, in wsgi_app
    response = self.full_dispatch_request()
  File "/usr/local/lib/python3.7/dist-packages/flask/app.py", line 1951, in full_dispatch_request
    rv = self.handle_user_exception(e)
  File "/usr/local/lib/python3.7/dist-packages/flask/app.py", line 1820, in handle_user_exception
    reraise(exc_type, exc_value, tb)
  File "/usr/local/lib/python3.7/dist-packages/flask/_compat.py", line 39, in reraise
    raise value
  File "/usr/local/lib/python3.7/dist-packages/flask/app.py", line 1949, in full_dispatch_request
    rv = self.dispatch_request()
  File "/usr/local/lib/python3.7/dist-packages/flask/app.py", line 1935, in dispatch_request
    return self.view_functions[rule.endpoint](**req.view_args)
  File "/usr/local/lib/python3.7/dist-packages/flask_login/utils.py", line 261, in decorated_view
    return func(*args, **kwargs)
  File "/home/harshalgangurde/Workspace/Flask/microblog/app/routes.py", line 79, in edit_profile
    db.session.commit()
  File "/usr/local/lib/python3.7/dist-packages/sqlalchemy/orm/scoping.py", line 162, in do
    return getattr(self.registry(), name)(*args, **kwargs)
  File "/usr/local/lib/python3.7/dist-packages/sqlalchemy/orm/session.py", line 1027, in commit
    self.transaction.commit()
  File "/usr/local/lib/python3.7/dist-packages/sqlalchemy/orm/session.py", line 494, in commit
    self._prepare_impl()
  File "/usr/local/lib/python3.7/dist-packages/sqlalchemy/orm/session.py", line 473, in _prepare_impl
    self.session.flush()
  File "/usr/local/lib/python3.7/dist-packages/sqlalchemy/orm/session.py", line 2470, in flush
    self._flush(objects)
  File "/usr/local/lib/python3.7/dist-packages/sqlalchemy/orm/session.py", line 2608, in _flush
    transaction.rollback(_capture_exception=True)
  File "/usr/local/lib/python3.7/dist-packages/sqlalchemy/util/langhelpers.py", line 68, in __exit__
    compat.reraise(exc_type, exc_value, exc_tb)
  File "/usr/local/lib/python3.7/dist-packages/sqlalchemy/util/compat.py", line 153, in reraise
    raise value
  File "/usr/local/lib/python3.7/dist-packages/sqlalchemy/orm/session.py", line 2568, in _flush
    flush_context.execute()
  File "/usr/local/lib/python3.7/dist-packages/sqlalchemy/orm/unitofwork.py", line 422, in execute
    rec.execute(self)
  File "/usr/local/lib/python3.7/dist-packages/sqlalchemy/orm/unitofwork.py", line 589, in execute
    uow,
  File "/usr/local/lib/python3.7/dist-packages/sqlalchemy/orm/persistence.py", line 236, in save_obj
    update,
  File "/usr/local/lib/python3.7/dist-packages/sqlalchemy/orm/persistence.py", line 996, in _emit_update_statements
    statement, multiparams
  File "/usr/local/lib/python3.7/dist-packages/sqlalchemy/engine/base.py", line 982, in execute
    return meth(self, multiparams, params)
  File "/usr/local/lib/python3.7/dist-packages/sqlalchemy/sql/elements.py", line 287, in _execute_on_connection
    return connection._execute_clauseelement(self, multiparams, params)
  File "/usr/local/lib/python3.7/dist-packages/sqlalchemy/engine/base.py", line 1101, in _execute_clauseelement
    distilled_params,
  File "/usr/local/lib/python3.7/dist-packages/sqlalchemy/engine/base.py", line 1250, in _execute_context
    e, statement, parameters, cursor, context
  File "/usr/local/lib/python3.7/dist-packages/sqlalchemy/engine/base.py", line 1476, in _handle_dbapi_exception
    util.raise_from_cause(sqlalchemy_exception, exc_info)
  File "/usr/local/lib/python3.7/dist-packages/sqlalchemy/util/compat.py", line 398, in raise_from_cause
    reraise(type(exception), exception, tb=exc_tb, cause=cause)
  File "/usr/local/lib/python3.7/dist-packages/sqlalchemy/util/compat.py", line 152, in reraise
    raise value.with_traceback(tb)
  File "/usr/local/lib/python3.7/dist-packages/sqlalchemy/engine/base.py", line 1246, in _execute_context
    cursor, statement, parameters, context
  File "/usr/local/lib/python3.7/dist-packages/sqlalchemy/engine/default.py", line 581, in do_execute
    cursor.execute(statement, parameters)
sqlalchemy.exc.IntegrityError: (sqlite3.IntegrityError) UNIQUE constraint failed: user.username
[SQL: UPDATE user SET username=?, about_me=? WHERE user.id = ?]
[parameters: ('harsh', 'about me', 3)]
(Background on this error at: http://sqlalche.me/e/gkpj)
2019-11-15 12:22:30,096 INFO: Microblog Startup... [in /home/harshalgangurde/Workspace/Flask/microblog/app/__init__.py:29]
2019-11-15 12:22:48,009 ERROR: Exception on /edit-profile [POST] [in /usr/local/lib/python3.7/dist-packages/flask/app.py:1891]
Traceback (most recent call last):
  File "/usr/local/lib/python3.7/dist-packages/flask/app.py", line 2446, in wsgi_app
    response = self.full_dispatch_request()
  File "/usr/local/lib/python3.7/dist-packages/flask/app.py", line 1952, in full_dispatch_request
    return self.finalize_request(rv)
  File "/usr/local/lib/python3.7/dist-packages/flask/app.py", line 1967, in finalize_request
    response = self.make_response(rv)
  File "/usr/local/lib/python3.7/dist-packages/flask/app.py", line 2097, in make_response
    "The view function did not return a valid response. The"
TypeError: The view function did not return a valid response. The function either returned None or ended without a return statement.
2019-11-15 12:23:44,548 INFO: Microblog Startup... [in /home/harshalgangurde/Workspace/Flask/microblog/app/__init__.py:29]
2019-11-15 12:24:04,486 ERROR: Exception on /edit-profile [POST] [in /usr/local/lib/python3.7/dist-packages/flask/app.py:1891]
Traceback (most recent call last):
  File "/usr/local/lib/python3.7/dist-packages/flask/app.py", line 2446, in wsgi_app
    response = self.full_dispatch_request()
  File "/usr/local/lib/python3.7/dist-packages/flask/app.py", line 1952, in full_dispatch_request
    return self.finalize_request(rv)
  File "/usr/local/lib/python3.7/dist-packages/flask/app.py", line 1967, in finalize_request
    response = self.make_response(rv)
  File "/usr/local/lib/python3.7/dist-packages/flask/app.py", line 2097, in make_response
    "The view function did not return a valid response. The"
TypeError: The view function did not return a valid response. The function either returned None or ended without a return statement.
2019-11-15 12:30:23,127 INFO: Microblog Startup... [in /home/harshalgangurde/Workspace/Flask/microblog/app/__init__.py:29]
2019-11-15 12:30:40,371 ERROR: Exception on /edit-profile [POST] [in /usr/local/lib/python3.7/dist-packages/flask/app.py:1891]
Traceback (most recent call last):
  File "/usr/local/lib/python3.7/dist-packages/flask/app.py", line 2446, in wsgi_app
    response = self.full_dispatch_request()
  File "/usr/local/lib/python3.7/dist-packages/flask/app.py", line 1952, in full_dispatch_request
    return self.finalize_request(rv)
  File "/usr/local/lib/python3.7/dist-packages/flask/app.py", line 1967, in finalize_request
    response = self.make_response(rv)
  File "/usr/local/lib/python3.7/dist-packages/flask/app.py", line 2097, in make_response
    "The view function did not return a valid response. The"
TypeError: The view function did not return a valid response. The function either returned None or ended without a return statement.
